[2022-09-03T09:50:24.765+0000] {taskinstance.py:1171} INFO - Dependencies all met for <TaskInstance: weather_data.check_weather manual__2022-09-03T09:50:21.812513+00:00 [queued]>
[2022-09-03T09:50:24.771+0000] {taskinstance.py:1171} INFO - Dependencies all met for <TaskInstance: weather_data.check_weather manual__2022-09-03T09:50:21.812513+00:00 [queued]>
[2022-09-03T09:50:24.772+0000] {taskinstance.py:1368} INFO - 
--------------------------------------------------------------------------------
[2022-09-03T09:50:24.772+0000] {taskinstance.py:1369} INFO - Starting attempt 1 of 1
[2022-09-03T09:50:24.773+0000] {taskinstance.py:1370} INFO - 
--------------------------------------------------------------------------------
[2022-09-03T09:50:24.781+0000] {taskinstance.py:1389} INFO - Executing <Task(PythonOperator): check_weather> on 2022-09-03 09:50:21.812513+00:00
[2022-09-03T09:50:24.785+0000] {standard_task_runner.py:52} INFO - Started process 4999 to run task
[2022-09-03T09:50:24.787+0000] {standard_task_runner.py:79} INFO - Running: ['***', 'tasks', 'run', 'weather_data', 'check_weather', 'manual__2022-09-03T09:50:21.812513+00:00', '--job-id', '77', '--raw', '--subdir', 'DAGS_FOLDER/first_dag.py', '--cfg-path', '/tmp/tmpk9u54gdg', '--error-file', '/tmp/tmpzl45les6']
[2022-09-03T09:50:24.788+0000] {standard_task_runner.py:80} INFO - Job 77: Subtask check_weather
[2022-09-03T09:50:24.829+0000] {task_command.py:371} INFO - Running <TaskInstance: weather_data.check_weather manual__2022-09-03T09:50:21.812513+00:00 [running]> on host 3d56073112d8
[2022-09-03T09:50:24.871+0000] {taskinstance.py:1583} INFO - Exporting the following env vars:
AIRFLOW_CTX_DAG_OWNER=***
AIRFLOW_CTX_DAG_ID=weather_data
AIRFLOW_CTX_TASK_ID=check_weather
AIRFLOW_CTX_EXECUTION_DATE=2022-09-03T09:50:21.812513+00:00
AIRFLOW_CTX_TRY_NUMBER=1
AIRFLOW_CTX_DAG_RUN_ID=manual__2022-09-03T09:50:21.812513+00:00
[2022-09-03T09:50:24.886+0000] {taskinstance.py:1902} ERROR - Task failed with exception
Traceback (most recent call last):
  File "/home/airflow/.local/lib/python3.7/site-packages/airflow/operators/python.py", line 171, in execute
    return_value = self.execute_callable()
  File "/home/airflow/.local/lib/python3.7/site-packages/airflow/operators/python.py", line 189, in execute_callable
    return self.python_callable(*self.op_args, **self.op_kwargs)
  File "/opt/airflow/dags/first_dag.py", line 30, in context_handler
    return response.get('main')[0].get('temp')
KeyError: 0
[2022-09-03T09:50:24.893+0000] {taskinstance.py:1412} INFO - Marking task as FAILED. dag_id=weather_data, task_id=check_weather, execution_date=20220903T095021, start_date=20220903T095024, end_date=20220903T095024
[2022-09-03T09:50:24.900+0000] {standard_task_runner.py:97} ERROR - Failed to execute job 77 for task check_weather (0; 4999)
[2022-09-03T09:50:24.920+0000] {local_task_job.py:156} INFO - Task exited with return code 1
[2022-09-03T09:50:24.940+0000] {local_task_job.py:279} INFO - 0 downstream tasks scheduled from follow-on schedule check
