[2022-09-03T06:00:00.840+0000] {taskinstance.py:1171} INFO - Dependencies all met for <TaskInstance: weather_data.getting_weather scheduled__2022-09-03T05:00:00+00:00 [queued]>
[2022-09-03T06:00:00.848+0000] {taskinstance.py:1171} INFO - Dependencies all met for <TaskInstance: weather_data.getting_weather scheduled__2022-09-03T05:00:00+00:00 [queued]>
[2022-09-03T06:00:00.849+0000] {taskinstance.py:1368} INFO - 
--------------------------------------------------------------------------------
[2022-09-03T06:00:00.850+0000] {taskinstance.py:1369} INFO - Starting attempt 1 of 1
[2022-09-03T06:00:00.850+0000] {taskinstance.py:1370} INFO - 
--------------------------------------------------------------------------------
[2022-09-03T06:00:00.858+0000] {taskinstance.py:1389} INFO - Executing <Task(SimpleHttpOperator): getting_weather> on 2022-09-03 05:00:00+00:00
[2022-09-03T06:00:00.863+0000] {standard_task_runner.py:52} INFO - Started process 1171 to run task
[2022-09-03T06:00:00.865+0000] {standard_task_runner.py:79} INFO - Running: ['***', 'tasks', 'run', 'weather_data', 'getting_weather', 'scheduled__2022-09-03T05:00:00+00:00', '--job-id', '7', '--raw', '--subdir', 'DAGS_FOLDER/first_dag.py', '--cfg-path', '/tmp/tmpugm6cvep', '--error-file', '/tmp/tmpnvho5gsw']
[2022-09-03T06:00:00.866+0000] {standard_task_runner.py:80} INFO - Job 7: Subtask getting_weather
[2022-09-03T06:00:00.908+0000] {task_command.py:371} INFO - Running <TaskInstance: weather_data.getting_weather scheduled__2022-09-03T05:00:00+00:00 [running]> on host 3d56073112d8
[2022-09-03T06:00:00.953+0000] {taskinstance.py:1583} INFO - Exporting the following env vars:
AIRFLOW_CTX_DAG_OWNER=***
AIRFLOW_CTX_DAG_ID=weather_data
AIRFLOW_CTX_TASK_ID=getting_weather
AIRFLOW_CTX_EXECUTION_DATE=2022-09-03T05:00:00+00:00
AIRFLOW_CTX_TRY_NUMBER=1
AIRFLOW_CTX_DAG_RUN_ID=scheduled__2022-09-03T05:00:00+00:00
[2022-09-03T06:00:00.954+0000] {http.py:121} INFO - Calling HTTP method
[2022-09-03T06:00:00.961+0000] {base.py:68} INFO - Using connection ID 'http_default' for task execution.
[2022-09-03T06:00:00.963+0000] {http.py:148} INFO - Sending 'POST' to url: http://api.openweathermap.org/data/2.5/weather
[2022-09-03T06:00:02.132+0000] {http.py:161} ERROR - HTTP error: Unauthorized
[2022-09-03T06:00:02.137+0000] {http.py:162} ERROR - {"cod":401, "message": "Invalid API key. Please see http://openweathermap.org/faq#error401 for more info."}
[2022-09-03T06:00:02.160+0000] {taskinstance.py:1902} ERROR - Task failed with exception
Traceback (most recent call last):
  File "/home/airflow/.local/lib/python3.7/site-packages/airflow/providers/http/hooks/http.py", line 159, in check_response
    response.raise_for_status()
  File "/home/airflow/.local/lib/python3.7/site-packages/requests/models.py", line 1022, in raise_for_status
    raise HTTPError(http_error_msg, response=self)
requests.exceptions.HTTPError: 401 Client Error: Unauthorized for url: http://api.openweathermap.org/data/2.5/weather

During handling of the above exception, another exception occurred:

Traceback (most recent call last):
  File "/home/airflow/.local/lib/python3.7/site-packages/airflow/providers/http/operators/http.py", line 123, in execute
    response = http.run(self.endpoint, self.data, self.headers, self.extra_options)
  File "/home/airflow/.local/lib/python3.7/site-packages/airflow/providers/http/hooks/http.py", line 149, in run
    return self.run_and_check(session, prepped_request, extra_options)
  File "/home/airflow/.local/lib/python3.7/site-packages/airflow/providers/http/hooks/http.py", line 202, in run_and_check
    self.check_response(response)
  File "/home/airflow/.local/lib/python3.7/site-packages/airflow/providers/http/hooks/http.py", line 163, in check_response
    raise AirflowException(str(response.status_code) + ":" + response.reason)
airflow.exceptions.AirflowException: 401:Unauthorized
[2022-09-03T06:00:02.165+0000] {taskinstance.py:1412} INFO - Marking task as FAILED. dag_id=weather_data, task_id=getting_weather, execution_date=20220903T050000, start_date=20220903T060000, end_date=20220903T060002
[2022-09-03T06:00:02.177+0000] {standard_task_runner.py:97} ERROR - Failed to execute job 7 for task getting_weather (401:Unauthorized; 1171)
[2022-09-03T06:00:02.221+0000] {local_task_job.py:156} INFO - Task exited with return code 1
[2022-09-03T06:00:02.246+0000] {local_task_job.py:279} INFO - 0 downstream tasks scheduled from follow-on schedule check
