[2022-09-03T08:29:12.425+0000] {taskinstance.py:1171} INFO - Dependencies all met for <TaskInstance: weather_data.getting_weather scheduled__2022-09-03T07:00:00+00:00 [queued]>
[2022-09-03T08:29:12.442+0000] {taskinstance.py:1171} INFO - Dependencies all met for <TaskInstance: weather_data.getting_weather scheduled__2022-09-03T07:00:00+00:00 [queued]>
[2022-09-03T08:29:12.443+0000] {taskinstance.py:1368} INFO - 
--------------------------------------------------------------------------------
[2022-09-03T08:29:12.445+0000] {taskinstance.py:1369} INFO - Starting attempt 1 of 1
[2022-09-03T08:29:12.446+0000] {taskinstance.py:1370} INFO - 
--------------------------------------------------------------------------------
[2022-09-03T08:29:12.480+0000] {taskinstance.py:1389} INFO - Executing <Task(SimpleHttpOperator): getting_weather> on 2022-09-03 07:00:00+00:00
[2022-09-03T08:29:12.490+0000] {standard_task_runner.py:52} INFO - Started process 1255 to run task
[2022-09-03T08:29:12.505+0000] {standard_task_runner.py:79} INFO - Running: ['***', 'tasks', 'run', 'weather_data', 'getting_weather', 'scheduled__2022-09-03T07:00:00+00:00', '--job-id', '11', '--raw', '--subdir', 'DAGS_FOLDER/first_dag.py', '--cfg-path', '/tmp/tmpfhi3ny1a', '--error-file', '/tmp/tmpgevqzvzr']
[2022-09-03T08:29:12.512+0000] {standard_task_runner.py:80} INFO - Job 11: Subtask getting_weather
[2022-09-03T08:29:12.610+0000] {task_command.py:371} INFO - Running <TaskInstance: weather_data.getting_weather scheduled__2022-09-03T07:00:00+00:00 [running]> on host 3d56073112d8
[2022-09-03T08:29:12.703+0000] {taskinstance.py:1583} INFO - Exporting the following env vars:
AIRFLOW_CTX_DAG_OWNER=***
AIRFLOW_CTX_DAG_ID=weather_data
AIRFLOW_CTX_TASK_ID=getting_weather
AIRFLOW_CTX_EXECUTION_DATE=2022-09-03T07:00:00+00:00
AIRFLOW_CTX_TRY_NUMBER=1
AIRFLOW_CTX_DAG_RUN_ID=scheduled__2022-09-03T07:00:00+00:00
[2022-09-03T08:29:12.705+0000] {http.py:121} INFO - Calling HTTP method
[2022-09-03T08:29:12.721+0000] {base.py:68} INFO - Using connection ID 'http_default' for task execution.
[2022-09-03T08:29:12.726+0000] {http.py:148} INFO - Sending 'POST' to url: http://api.openweathermap.org/data/2.5/weather
[2022-09-03T08:29:12.895+0000] {http.py:161} ERROR - HTTP error: Unauthorized
[2022-09-03T08:29:12.897+0000] {http.py:162} ERROR - {"cod":401, "message": "Invalid API key. Please see http://openweathermap.org/faq#error401 for more info."}
[2022-09-03T08:29:12.906+0000] {taskinstance.py:1902} ERROR - Task failed with exception
Traceback (most recent call last):
  File "/home/airflow/.local/lib/python3.7/site-packages/airflow/providers/http/hooks/http.py", line 159, in check_response
    response.raise_for_status()
  File "/home/airflow/.local/lib/python3.7/site-packages/requests/models.py", line 1022, in raise_for_status
    raise HTTPError(http_error_msg, response=self)
requests.exceptions.HTTPError: 401 Client Error: Unauthorized for url: http://api.openweathermap.org/data/2.5/weather

During handling of the above exception, another exception occurred:

Traceback (most recent call last):
  File "/home/airflow/.local/lib/python3.7/site-packages/airflow/providers/http/operators/http.py", line 123, in execute
    response = http.run(self.endpoint, self.data, self.headers, self.extra_options)
  File "/home/airflow/.local/lib/python3.7/site-packages/airflow/providers/http/hooks/http.py", line 149, in run
    return self.run_and_check(session, prepped_request, extra_options)
  File "/home/airflow/.local/lib/python3.7/site-packages/airflow/providers/http/hooks/http.py", line 202, in run_and_check
    self.check_response(response)
  File "/home/airflow/.local/lib/python3.7/site-packages/airflow/providers/http/hooks/http.py", line 163, in check_response
    raise AirflowException(str(response.status_code) + ":" + response.reason)
airflow.exceptions.AirflowException: 401:Unauthorized
[2022-09-03T08:29:12.910+0000] {taskinstance.py:1412} INFO - Marking task as FAILED. dag_id=weather_data, task_id=getting_weather, execution_date=20220903T070000, start_date=20220903T082912, end_date=20220903T082912
[2022-09-03T08:29:12.918+0000] {standard_task_runner.py:97} ERROR - Failed to execute job 11 for task getting_weather (401:Unauthorized; 1255)
[2022-09-03T08:29:12.954+0000] {local_task_job.py:156} INFO - Task exited with return code 1
[2022-09-03T08:29:12.977+0000] {local_task_job.py:279} INFO - 0 downstream tasks scheduled from follow-on schedule check
