[2022-09-03T09:45:06.533+0000] {taskinstance.py:1171} INFO - Dependencies all met for <TaskInstance: weather_data.check_weather manual__2022-09-03T09:45:03.706470+00:00 [queued]>
[2022-09-03T09:45:06.540+0000] {taskinstance.py:1171} INFO - Dependencies all met for <TaskInstance: weather_data.check_weather manual__2022-09-03T09:45:03.706470+00:00 [queued]>
[2022-09-03T09:45:06.540+0000] {taskinstance.py:1368} INFO - 
--------------------------------------------------------------------------------
[2022-09-03T09:45:06.541+0000] {taskinstance.py:1369} INFO - Starting attempt 1 of 1
[2022-09-03T09:45:06.542+0000] {taskinstance.py:1370} INFO - 
--------------------------------------------------------------------------------
[2022-09-03T09:45:06.550+0000] {taskinstance.py:1389} INFO - Executing <Task(PythonOperator): check_weather> on 2022-09-03 09:45:03.706470+00:00
[2022-09-03T09:45:06.554+0000] {standard_task_runner.py:52} INFO - Started process 4701 to run task
[2022-09-03T09:45:06.556+0000] {standard_task_runner.py:79} INFO - Running: ['***', 'tasks', 'run', 'weather_data', 'check_weather', 'manual__2022-09-03T09:45:03.706470+00:00', '--job-id', '62', '--raw', '--subdir', 'DAGS_FOLDER/first_dag.py', '--cfg-path', '/tmp/tmpmtive2q_', '--error-file', '/tmp/tmpigs5qzeh']
[2022-09-03T09:45:06.557+0000] {standard_task_runner.py:80} INFO - Job 62: Subtask check_weather
[2022-09-03T09:45:06.597+0000] {task_command.py:371} INFO - Running <TaskInstance: weather_data.check_weather manual__2022-09-03T09:45:03.706470+00:00 [running]> on host 3d56073112d8
[2022-09-03T09:45:06.646+0000] {taskinstance.py:1583} INFO - Exporting the following env vars:
AIRFLOW_CTX_DAG_OWNER=***
AIRFLOW_CTX_DAG_ID=weather_data
AIRFLOW_CTX_TASK_ID=check_weather
AIRFLOW_CTX_EXECUTION_DATE=2022-09-03T09:45:03.706470+00:00
AIRFLOW_CTX_TRY_NUMBER=1
AIRFLOW_CTX_DAG_RUN_ID=manual__2022-09-03T09:45:03.706470+00:00
[2022-09-03T09:45:06.655+0000] {taskinstance.py:1902} ERROR - Task failed with exception
Traceback (most recent call last):
  File "/home/airflow/.local/lib/python3.7/site-packages/airflow/operators/python.py", line 171, in execute
    return_value = self.execute_callable()
  File "/home/airflow/.local/lib/python3.7/site-packages/airflow/operators/python.py", line 189, in execute_callable
    return self.python_callable(*self.op_args, **self.op_kwargs)
  File "/opt/airflow/dags/first_dag.py", line 20, in context_handler
    ti.xcom_push(key='description', value=response.get('weather').get('description'))
AttributeError: 'list' object has no attribute 'get'
[2022-09-03T09:45:06.667+0000] {taskinstance.py:1412} INFO - Marking task as FAILED. dag_id=weather_data, task_id=check_weather, execution_date=20220903T094503, start_date=20220903T094506, end_date=20220903T094506
[2022-09-03T09:45:06.680+0000] {standard_task_runner.py:97} ERROR - Failed to execute job 62 for task check_weather ('list' object has no attribute 'get'; 4701)
[2022-09-03T09:45:06.688+0000] {local_task_job.py:156} INFO - Task exited with return code 1
[2022-09-03T09:45:06.708+0000] {local_task_job.py:279} INFO - 0 downstream tasks scheduled from follow-on schedule check
